Workbook
Name Print_Area: Bankgespräch!$A$5:$L$55
Name Print_Area: Cockpit!$A$5:$X$47
Name Print_Area: Deckblatt!$B$6:$M$38
Name Print_Area: Diagramme!$A$5:$S$106
Name Print_Area: Haushaltsrechnung!$B$6:$P$51
Name Print_Area: Hinweise_AT!$A$5:$O$116
Name Print_Area: Konfiguration!$A$5:$F$13
Name Print_Area: 'MFH-Kalkulator'!$A$5:$BC$224
Name Print_Area: 'Miete, Cashflow, Steuern'!$A$5:$BB$44
Name Print_Area: Sanierungsplaner!$A$6:$L$240
Name Print_Area: Szenarien!$A$5:$AW$32
Name Print_Area: Vermögensaufstellung!$B$6:$P$39
Name Print_Area: 'Wert, AfA, Darlehen'!$A$5:$BB$120
Name Print_Titles: 'MFH-Kalkulator'!$A:$D
Name Print_Titles: 'Miete, Cashflow, Steuern'!$A:$C
Name Print_Titles: 'Wert, AfA, Darlehen'!$A:$C

Sheet Deckblatt
B1: zurück zum Cockpit
C7: immocation
C18: Bei dieser Excel-Datei handelt es sich um ein kostenpflichtiges Produkt, welches unter der u.s. Internetadresse erworben werden kann. Die Datei darf ohne Zustimmung weder vervielfältigt, noch weitergegeben oder sonst irgendwie anderen Benutzern zugänglich gemacht werden. Microsoft Excel ist ein Produkt der Firma Microsoft. Wir stehen in keinerlei rechtlicher Beziehung zu Microsoft und handeln auch nicht in Microsofts Namen. Wir weisen ausdrücklich darauf hin, dass wir keinerlei Rechts-, Steuer- oder Finanzberatung erbringen und die geschilderte Rechtslage zum Teil zur besseren Verständlichkeit und Lesbarkeit außerdem auch vereinfacht dargestellt wurde. Alle von uns erteilten Ratschläge fußen ausschließlich auf unserer persönlichen Erfahrung und unserer persönlichen Meinung. Auch wenn wir jede unserer Empfehlungen mit größtmöglicher Sorgfalt und umfangreicher Recherche entwickelt und fortlaufend kritisch hinterfragt haben, können wir hierfür keinerlei Gewähr bieten. Gleiches gilt auch für die Vollständigkeit und Richtigkeit der dargestellten Rechtslage. Die erteilten Ratschläge können ferner auch keine fundierte und auf den Einzelfall zugeschnittene Rechts-, Steuer- oder Finanzberatung ersetzen. Wir können daher weder eine Erfolgsgarantie für die von uns abgegebenen Empfehlungen noch eine Haftung für evtl. Folgen ihrer Anwendung übernehmen. Auch sämtliche Kalkulationstools wurden mit größter Sorgfalt erstellt. Wir haben durch mehrfache Überprüfungen bestmöglich versucht, Berechnungsfehler auszuschließen. Trotzdem können Fehler nicht vollständig ausgeschlossen werden. Daher können wir keine juristische Verantwortung und keinerlei Haftung für eventuell verbliebene Fehler und deren Folgen übernehmen. Um etwaige Fehler so weit wie möglich auszuschließen, empfehlen wir dringend und in jedem Fall eigenständige Kontrollrechnungen durchzuführen und ggf. zusätzlichen Fachrat eines Rechts-, Steuer- oder Finanzberaters einzuholen.
C41: Copyright 2020
C42: www.immocation.de

Sheet Cockpit
C1: Cockpit | D1: Bankgespräch | G1: Kennzahlen im Verlauf | J1: Szenarien-Vergleich | M1: Diagramme | N1: MFH | P1: Sanierungsplaner | S1: Tabelle entsperren
B6: Objekt und Investition | G6: Miete, Steuern, Rücklagen | J6: Bewirtschaftungskosten | M6: Finanzierung | P6: Kennzahlen heute | S6: Kennzahlen in der Zukunft | V6: Profi Kenzahlen
B8: Objekt und Kaufdatum | G8: Soll-Miete pro Monat | J8: Bewirtschaftungskosten pro Monat | M8: Gesamt-Finanzierung | P8: Vermögenszuwachs | S8: Betrachtungszeitpunkt | V8: Break-Even
B9: Adresse | C9: Rapfstraße 3/1, Hollabrunn | G9: Kaltmiete Wohnfläche pro qm | H9: 12.5 | J9: Umlegbar | K9: =K23 -> 111 | M9: Darlehenssumme | N9: =N17+N25+N32+N39 -> 100000 | P9: Vermögenszuwachs p.a. | Q9: =12*(-Q22+Q25)+'Wert, AfA, Darlehen'!D11 -> 3607.115 | S9: Hochrechnung für das Jahr | T9: 2044 | V9: Cashflow nach Steuern erstmals positiv | W9: =IFERROR(OFFSET('Miete, Cashflow, Steuern'!C18,0,MATCH(TRUE,INDEX('Miete, Cashflow, Steuern'!$D$28:$BA$28>0,0),0)),"-") -> 2046
B10: Kaufdatum | C10: 45413 | D10: Kürzel | E10: BoEl19 | G10: Kaltmiete Wohnfläche gesamt | H10: =C11*H9 -> 529.375 | J10: Nicht umlegbar | K10: =K30 -> 99.502917 | M10: Eigenkapital | N10: =E35-N9 -> 38325 | P10: ohne Wertsteigerung | Q10: =Q9-'Wert, AfA, Darlehen'!D11 -> 1107.115 | S10: entspricht Jahre nach dem Kauf | T10: =T9-'Wert, AfA, Darlehen'!D37 -> 20 | V10: Kumulierter Cashflow bis dahin | W10: =OFFSET('Miete, Cashflow, Steuern'!C32,0,MATCH(TRUE,INDEX('Miete, Cashflow, Steuern'!$D$28:$BA$28>0,0),0)-1) -> -17087.019
B11: Wohnfläche | C11: 42.35 | D11: Stellplätze | E11: 1 | G11: + Stellplätze | H11: 0 | J11: entspricht % der Nettokaltmiete | K11: =K10/H15 -> 0.18796301 | M11: Zinssatz gewichtet | N11: =IF(N9=0,"n/a",((N18*$N$17)+(N26*$N$25)+(N33*$N$32)+(N40*$N$39))/$N$9) -> 0.037 | V11: Kumulierter Cashflow erstmals positiv | W11: =IFERROR(OFFSET('Miete, Cashflow, Steuern'!C18,0,MATCH(TRUE,INDEX('Miete, Cashflow, Steuern'!$D$32:$BA$32>0,0),0)),"-") -> 2049
G12: + Sonstiges | H12: 0 | J12: Insgesamt | K12: =K9+K10 -> 210.50292 | M12: Anfängliche Tilgung gewichtet | N12: =IF(N9=0,"n/a",((N19*$N$17)+(N27*$N$25)+(N34*$N$32)+(N41*$N$39))/$N$9) -> 0.023 | P12: Miete und Mietrendite | S12: Miete und Wert | V12: Kum. Cashflow inkl. EK erstmals positiv | W12: =IFERROR(OFFSET('Miete, Cashflow, Steuern'!C18,0,MATCH(TRUE,INDEX('Miete, Cashflow, Steuern'!$D$33:$BA$33>0,0),0)),"-") -> 2054
B13: Kaufpreis und Kaufnebenkosten | G13: = Nettokaltmiete | H13: =H10+H11+H12 -> 529.375 | M13: Annuität pro Monat | N13: =N20+N28+N35+N42 -> 500 | P13: Nettokaltmiete pro Jahr | Q13: =12*H15 -> 6352.5 | S13: Nettokaltmiete pro Jahr | T13: =OFFSET('Miete, Cashflow, Steuern'!D12,,Cockpit!T10)*12 -> 11139.147
B14: Kaufpreis | D14: 125000 | G14: Nettokaltmiete laut MFH-Kalkulator | H14: ='MFH-Kalkulator'!E12 -> 1287.5 | P14: Bruttomietrendite | Q14: =Q13/D14 -> 0.05082 | S14: pro qm und Monat | T14: =T13/12/C11 -> 21.918826 | V14: Wertschätzung über Kaufpreisfaktor
B15: pro m² | D15: =D14/C11 -> 2951.5939 | G15: = Nettokaltmiete (effektiv) | H15: =IF('MFH-Kalkulator'!$C$6="Ein",H14,H13) -> 529.375 | J15: Betriebskosten | M15: Darlehen I | P15: Faktor | Q15: =D14/Q13 -> 19.677292 | S15: Wert der Immobilie (Jahresende) | T15: =OFFSET('Wert, AfA, Darlehen'!E8,,Cockpit!T10) -> 189458.29 | V15: Nettokaltmiete pro Jahr | W15: =OFFSET('Miete, Cashflow, Steuern'!D12,,Cockpit!T10)*12 -> 11139.147
B16: Makler | D16: 0.036 | E16: =D16*$D$14 -> 4500 | G16: + umlegbare Bewirtschaftungskosten | H16: =K9 -> 111 | J16: Betriebskosten (insgesamt) | K16: 156 | M16: Darlehenssumme % Kaufpreis | N16: 0.8 | P16: Nettomietrendite | Q16: =(Q13-12*K10)/E35 -> 0.037292355 | S16: pro qm | T16: =T15/C11 -> 4473.6315 | V16: Faktor | W16: 15
B17: Notar | D17: 0.015 | E17: =D17*$D$14 -> 1875 | G17: = Bruttokaltmiete | H17: =H15+H16 -> 640.375 | J17: - enthaltene Reparaturrücklage | K17: 45 | M17: Darlehenssumme | N17: =N16*D14 -> 100000 | V17: Wert der Immobilie | W17: =W15*W16 -> 167087.21
B18: Grundbucheintragungsgeb. | D18: 0.011 | E18: =D18*$D$14 -> 1375 | J18: = umlegbare Betriebskosten | K18: =K16-K17 -> 111 | M18: Zinssatz | N18: 0.037 | P18: Cashflow pro Monat (Überschuss) | S18: Cashflow pro Monat (Überschuss) | V18: pro qm | W18: =W17/C11 -> 3945.3886
B19: Grunderwerbssteuer | D19: 0.035 | E19: =D19*$D$14 -> 4375 | G19: Steuern | M19: Anfängliche Tilgung | N19: 0.023 | P19: Bruttokaltmiete | Q19: =H17 -> 640.375 | S19: Bruttokaltmiete | T19: =OFFSET('Miete, Cashflow, Steuern'!D14,,Cockpit!T10) -> 1093.2024
B20: Sonstige | D20: 0 | E20: =D20*$D$14 -> 0 | G20: AfA Satz | H20: 0.015 | J20: Umlegbare Kosten | M20: Annuität pro Monat | N20: =(N18+N19)*N17/12 -> 500 | P20: - Bewirtschaftungskosten | Q20: =-K12 -> -210.50292 | S20: - Bewirtschaftungskosten | T20: =OFFSET('Miete, Cashflow, Steuern'!D23,,Cockpit!T10) -> -317.04543 | V20: Zinsänderungsrisiko
B21: Pfandrechtseintragungsgeb. | D21: 0.012 | E21: =D21*$N$9 -> 1200 | G21: Anteil Gebäude an Kaufpreis | H21: 0.6 | J21: Umlegbare Betriebskosten | K21: =K18 -> 111 | M21: Jahr der Volltilgung | N21: =IFERROR(HLOOKUP(0,'Wert, AfA, Darlehen'!D50:BA105,56,FALSE),"-") -> 2046 | P21: - Zinsen | Q21: =-N11*N9/12 -> -308.33333 | S21: - Zinsen | T21: =-OFFSET('Wert, AfA, Darlehen'!D110,,Cockpit!T10)/12 -> -44.313154 | V21: Monatl. Zinsen für CF 0 nach Steuern | W21: =-(T21-T25/(1-T33)) -> 28.416335
B22: Summe | D22: =SUM(D16:D21) -> 0.109 | E22: =SUM(E16:E21) -> 13325 | G22: Basis für langfristige Abschreibung | H22: =H21*(D14+E22-E21)+SUMIF(D26:D29,"Aktivieren",C26:C29) -> 82275 | J22: Sonstige umlegbare Kosten | K22: =K38 -> 0 | P22: - Tilgung | Q22: =-N12*N9/12 -> -191.66667 | S22: - Tilgung | T22: =-OFFSET('Wert, AfA, Darlehen'!D114,,Cockpit!T10)/12 -> -455.68685 | V22: = Zinssatz gewichtet (p.a.) | W22: =IF(OFFSET('Wert, AfA, Darlehen'!D106,,Cockpit!T10)=0,"n/a",W21*12/OFFSET('Wert, AfA, Darlehen'!D106,,Cockpit!T10)) -> 0.023726689
J23: Summe | K23: =SUM(K21:K22) -> 111 | P23: = Cashflow operativ | Q23: =SUM(Q19:Q22) -> -70.127917 | S23: = Cashflow operativ | T23: =SUM(T19:T22) -> 276.157
B24: Anfängliche Investitionen | G24: Rücklagen | M24: Darlehen II | P24: - Steuern | Q24: =-Q34 -> -29.279167 | S24: - Steuern | T24: =-T34 -> -285.69509 | V24: Vermögenszuwachs bis Jahresende
B25: Was | C25: Kosten | D25: Steuerlich | E25: Wertsteig. | G25: Kalkulatorischer Mietausfall | H25: 0.03 | J25: Nicht umlegbare Kosten | M25: Darlehenssumme | N25: 0 | P25: = Cashflow nach Steuern | Q25: =Q23+Q24 -> -99.407083 | S25: = Cashflow nach Steuern | T25: =T23+T24 -> -9.5380911 | V25: Wert der Immobilie | W25: =OFFSET('Wert, AfA, Darlehen'!E8,,Cockpit!T10) -> 189458.29
B26: Renovierung | C26: 0 | D26: 15 Jahre | G26: Eigene Instandhalt.-Rückl. (pro m² p.a.) | H26: 10 | J26: Reparaturrücklage in Betriebskosten | K26: =K17 -> 45 | M26: Zinssatz | N26: 0.02 | V26: - Restschuld Darlehen | W26: =-OFFSET('Wert, AfA, Darlehen'!D118,,Cockpit!T10) -> -8903.5915
D27: Sofort | G27: Empfohlene eigene Instandhalt.-Rückl. | H27: =((H21*D14)*(1/80*1.5)-(12*K26))/C11 -> 20.454545 | J27: + Eigene Instandhaltungsrücklage | K27: =C11*H26/12 -> 35.291667 | M27: Anfängliche Tilgung | N27: 0.08 | P27: Nebenrechnung Steuer (Monatsbasis) | S27: Nebenrechnung Steuer (Monatsbasis) | V27: - Eigenkapital Einsatz | W27: =-N10 -> -38325
D28: Sofort | J28: + Kalkulatorischer Mietausfall | K28: =H25*H17 -> 19.21125 | M28: Annuität pro Monat | N28: =(N26+N27)*N25/12 -> 0 | P28: Bruttokaltmiete | Q28: =Q19 -> 640.375 | S28: Bruttokaltmiete | T28: =T19 -> 1093.2024 | V28: + Kumulierter Cashflow | W28: =OFFSET('Miete, Cashflow, Steuern'!D32,,Cockpit!T10) -> -17058.709
D29: Sofort | G29: Prognose | J29: + Sonstige nicht umlegbare Kosten | K29: =K46 -> 0 | M29: Jahr der Volltilgung | N29: =HLOOKUP(0,'Wert, AfA, Darlehen'!D67:BA105,39,FALSE) -> 2024 | P29: - Bewirt.-Kosten ohne eigene Rückl. | Q29: =-K12+K27+K28 -> -156 | S29: - Bewirt.-Kosten ohne eigene Rückl. | T29: =OFFSET('Miete, Cashflow, Steuern'!D38,,Cockpit!T10) -> -231.80779 | V29: = Vermögenszuwachs | W29: =SUM(W25:W28) -> 125170.99
B30: Summe | C30: =SUM(C26:C29) -> 0 | D30: Summe | E30: =SUM(E26:E29) -> 0 | G30: Kostensteigerung p.a. | H30: 0.02 | J30: = Summe | K30: =K26+K27+K28+K29 -> 99.502917 | P30: - Zinsen | Q30: =Q21 -> -308.33333 | S30: - Zinsen | T30: =T21 -> -44.313154
B31: Neuer Wert | E31: =D14+E30 -> 125000 | G31: Mietsteigerung p.a. | H31: 0.03 | M31: Darlehen III | P31: - Abschreibung (AfA) | Q31: =-'Wert, AfA, Darlehen'!D19-'Wert, AfA, Darlehen'!D24-IF(E32="Abziehen",'Wert, AfA, Darlehen'!D34,'Wert, AfA, Darlehen'!D34-'Wert, AfA, Darlehen'!D28/12) -> -102.84375 | S31: - Abschreibung (AfA) | T31: =OFFSET('Miete, Cashflow, Steuern'!D40,,Cockpit!T10) -> -102.84375 | V31: Beleihungsreserve
B32: Sofort abzugsfähige Kosten im Cashflow | E32: Ignorieren | G32: Wertsteigerung p.a. | H32: 0.02 | J32: Sonstige umlegbare Kosten (Details) | M32: Darlehenssumme | N32: 0 | P32: = zu versteuernder Cashflow | Q32: =SUM(Q28:Q31) -> 73.197917 | S32: = zu versteuernder Cashflow | T32: =SUM(T28:T31) -> 714.23773 | V32: Wert der Immobilie | W32: =W25 -> 189458.29
J33: Kostenposition I | M33: Zinssatz | N33: 0.03 | P33: * persönlicher Grenzsteuersatz | Q33: 0.4 | S33: * persönlicher Grenzsteuersatz | T33: =OFFSET('Miete, Cashflow, Steuern'!D42,,Cockpit!T10) -> 0.4 | V33: - Restschuld Darlehen | W33: =W26 -> -8903.5915
B34: Gesamtinvestitionskosten | J34: Kostenposition II | M34: Anfängliche Tilgung | N34: 0.05 | P34: = Steuern | Q34: =Q33*Q32 -> 29.279167 | S34: = Steuern | T34: =T33*T32 -> 285.69509 | V34: = Beleihungsreserve | W34: =W32+W33 -> 180554.7
B35: Summe | E35: =D14+E22+C30 -> 138325 | J35: Kostenposition III | M35: Annuität pro Monat | N35: =(N33+N34)*N32/12 -> 0
J36: Kostenposition IV | M36: Jahr der Volltilgung | N36: =HLOOKUP(0,'Wert, AfA, Darlehen'!D84:BA105,22,FALSE) -> 2024 | P36: Eigenkapitalrendite | V36: Kontostand
B37: Hinweis für Investoren aus Österreich: Das Tool geht davon aus, dass der Eigentümer hinsichtlich seiner Mieteinnahmen nicht der Umsatzsteuerpflicht unterliegt, also < 35.000 Euro jährliche Mieteinnahmen hat. Auf dem Tabellenblatt "Hinweise_AT" findest du weitere steuerliche Hinweise für Investoren aus Österreich. | J37: Weitere Kosten | P37: Eigenkapitalrendite p.a. | Q37: =IF(N10>0,Q9/N10,"n/a") -> 0.094119113 | V37: Eigenkapital Einsatz (anfänglich) | W37: =W27 -> -38325
J38: Summe | K38: =SUM(K33:K37) -> 0 | M38: Darlehen IV | P38: ohne Wertsteigerung | Q38: =Q10/N10 -> 0.028887541 | V38: + Kumulierter Cashflow | W38: =W28 -> -17058.709
M39: Darlehenssumme | N39: 0 | V39: = Kontostand | W39: =W37+W38 -> -55383.709
J40: Sonstige nicht umlegbare Kosten (Details) | M40: Zinssatz
J41: Kostenposition I | M41: Anfängliche Tilgung
B42: Zu den Hinweisen | J42: Kostenposition II | M42: Annuität pro Monat | N42: =(N40+N41)*N39/12 -> 0
J43: Kostenposition III | M43: Jahr der Volltilgung | N43: =HLOOKUP(0,'Wert, AfA, Darlehen'!D101:BA105,5,FALSE) -> 2024
J44: Kostenposition IV
J45: Weitere Kosten
...

Sheet Bankgespräch
C1: zurück zum Cockpit | E1: Bankgespräch
B6: Investitionsübersicht für das Bankgespräch | N6: Erhalte bessere Darlehen:
C8: =Cockpit!C9 -> Rapfstraße 3/1, Hollabrunn | I8: =Cockpit!C10 -> 45413 | N8: Drucke diese Übersicht aus, um deiner Bank dein Investment vorzustellen. Alle Zahlen stammen aus den vorhandenen Berechnungen. Für noch mehr Transparenz drucke auch die Tabelle "Cockpit". So zeigst du, dass du deine Zahlen wirklich im Griff hast und erhöhst deine Chance auf beste Konditionen.
N18: Um deiner Bank deine persönlichen finanziellen Verhältnisse darzustellen, kannst du folgende Vorlagen verwenden:
N23: zur Vorlage: Haushaltsrechnung
N24: zur Vorlage: Vermögensübersicht
C25: Investition | F25: Finanzierung | I25: Rentabilität
C27: Objektdetails | F27: Haupt-Darlehen | I27: Erwartete Mieteinkünfte | N27: Um die Bilder zu ändern, klicke mit rechts auf das Bild und wähle "Bild ändern".
C28: Wohnfläche | D28: =Cockpit!C11 -> 42.35 | F28: Summe | G28: =Cockpit!N17 -> 100000 | I28: Nettokaltmiete | J28: =Cockpit!H15 -> 529.375
C29: Kaufpreis pro qm | D29: =D33/D28 -> 2951.5939 | F29: Anfängliche Tilgung | G29: =Cockpit!N19 -> 0.023 | I29: Bruttomietrendite | J29: =Cockpit!Q14 -> 0.05082
F30: Annahme Zinsen | G30: =Cockpit!N18 -> 0.037 | I30: Kaufpreis Multiplikator | J30: =Cockpit!Q15 -> 19.677292
C32: Kapitalbedarf | F32: Weitere Darlehen | I32: Monatlicher Cashflow (Jahr 1)
C33: Kaufpreis | D33: =Cockpit!D14 -> 125000 | F33: Summe | G33: =Cockpit!N9-Cockpit!N17 -> 0 | I33: Nettokaltmiete | J33: =Cockpit!H15 -> 529.375
C34: Kaufnebenkosten | D34: =Cockpit!E22 -> 13325 | F34: Anfängliche Tilgung | G34: =(Cockpit!N12*Cockpit!N9-Cockpit!N19*Cockpit!N17)/(Cockpit!N9-Cockpit!N17) -> #DIV/0! | I34: =CONCATENATE("- Bewirtschaftungskosten (",TEXT(Cockpit!K11*100,"#"),"%)") -> - Bewirtschaftungskosten (19%) | J34: =Cockpit!K10 -> 99.502917
C35: Zusätzl. Investitionsbedarf | D35: =Cockpit!C30 -> 0 | F35: Annahme Zinsen | G35: =(Cockpit!N11*Cockpit!N9-Cockpit!N18*Cockpit!N17)/(Cockpit!N9-Cockpit!N17) -> #DIV/0! | I35: - Zinsen | J35: =-Cockpit!Q21 -> 308.33333
C36: Gesamtinvestitionskosten | D36: =SUM(D33:D35) -> 138325 | I36: - Tilgung | J36: =-Cockpit!Q22 -> 191.66667
F37: Eigenkapital | I37: = monatlicher Cashflow | J37: =J33-SUM(J34:J36) -> -70.127917
F38: Summe | G38: =Cockpit!N10 -> 38325
I42: Einnahme | J42: Ausgabe
H43: Nettokaltmiete | I43: =Cockpit!H15 -> 529.375
H44: Bewirt.-Kosten (nicht umlagefähig) | J44: =Cockpit!K10 -> 99.502917
H45: Zinsen | J45: =-Cockpit!Q21 -> 308.33333
H46: Tilgung | J46: =-Cockpit!Q22 -> 191.66667
B56: Keine Gewähr für die Richtigkeit der Angaben. Dieses Tool ersetzt keine fundierte Rechts-, Steuer- oder Finanzberatung. Mehr Details hier.

Sheet Miete, Cashflow, Steuern
B1: zurück zum Cockpit | E1: Miete, Cashflow, Steuern | J1: zu Wert, Abschreibung und Darlehen wechseln
B6: Miete pro Monat
D7: ='Wert, AfA, Darlehen'!D7 -> 2024 | E7: ='Wert, AfA, Darlehen'!E7 -> 2025 | F7: ='Wert, AfA, Darlehen'!F7 -> 2026 | G7: ='Wert, AfA, Darlehen'!G7 -> 2027 | H7: ='Wert, AfA, Darlehen'!H7 -> 2028 | I7: ='Wert, AfA, Darlehen'!I7 -> 2029 | J7: ='Wert, AfA, Darlehen'!J7 -> 2030 | K7: ='Wert, AfA, Darlehen'!K7 -> 2031 | ... BA7: ='Wert, AfA, Darlehen'!BA7 -> 2073
B8: Nettokaltmiete vor Erhöhung | E8: =D10 -> 529.375 | F8: =E10 -> 529.375 | G8: =F10 -> 545.25625 | H8: =G10 -> 561.61394 | I8: =H10 -> 578.46236 | J8: =I10 -> 595.81623 | K8: =J10 -> 613.69071 | L8: =K10 -> 632.10143 | ... BA8: =AZ10 -> 2123.7969
B9: + geplante Mieterhöhung | E9: 0 | F9: =Cockpit!$H$31 -> 0.03 | G9: =Cockpit!$H$31 -> 0.03 | H9: =Cockpit!$H$31 -> 0.03 | I9: =Cockpit!$H$31 -> 0.03 | J9: =Cockpit!$H$31 -> 0.03 | K9: =Cockpit!$H$31 -> 0.03 | L9: =Cockpit!$H$31 -> 0.03 | M9: =Cockpit!$H$31 -> 0.03 | ... BA9: =Cockpit!$H$31 -> 0.03
B10: = Nettokaltmiete | D10: =Cockpit!H15 -> 529.375 | E10: =E8*(1+E9) -> 529.375 | F10: =F8*(1+F9) -> 545.25625 | G10: =G8*(1+G9) -> 561.61394 | H10: =H8*(1+H9) -> 578.46236 | I10: =I8*(1+I9) -> 595.81623 | J10: =J8*(1+J9) -> 613.69071 | K10: =K8*(1+K9) -> 632.10143 | L10: =L8*(1+L9) -> 651.06448 | ... BA10: =BA8*(1+BA9) -> 2187.5108
B11: Nettokaltmiete laut MFH-Kalkulator | D11: ='MFH-Kalkulator'!E12 -> 1287.5 | E11: ='MFH-Kalkulator'!F12 -> 1326.125 | F11: ='MFH-Kalkulator'!G12 -> 1365.9088 | G11: ='MFH-Kalkulator'!H12 -> 1406.886 | H11: ='MFH-Kalkulator'!I12 -> 1449.0926 | I11: ='MFH-Kalkulator'!J12 -> 1492.5654 | J11: ='MFH-Kalkulator'!K12 -> 1537.3423 | K11: ='MFH-Kalkulator'!L12 -> 1583.4626 | ... BA11: ='MFH-Kalkulator'!BB12 -> 5479.8825
B12: = Nettokaltmiete (effektiv) | D12: =IF('MFH-Kalkulator'!$C$6="Ein",'Miete, Cashflow, Steuern'!D11,'Miete, Cashflow, Steuern'!D10) -> 529.375 | E12: =IF('MFH-Kalkulator'!$C$6="Ein",'Miete, Cashflow, Steuern'!E11,'Miete, Cashflow, Steuern'!E10) -> 529.375 | F12: =IF('MFH-Kalkulator'!$C$6="Ein",'Miete, Cashflow, Steuern'!F11,'Miete, Cashflow, Steuern'!F10) -> 545.25625 | G12: =IF('MFH-Kalkulator'!$C$6="Ein",'Miete, Cashflow, Steuern'!G11,'Miete, Cashflow, Steuern'!G10) -> 561.61394 | H12: =IF('MFH-Kalkulator'!$C$6="Ein",'Miete, Cashflow, Steuern'!H11,'Miete, Cashflow, Steuern'!H10) -> 578.46236 | I12: =IF('MFH-Kalkulator'!$C$6="Ein",'Miete, Cashflow, Steuern'!I11,'Miete, Cashflow, Steuern'!I10) -> 595.81623 | J12: =IF('MFH-Kalkulator'!$C$6="Ein",'Miete, Cashflow, Steuern'!J11,'Miete, Cashflow, Steuern'!J10) -> 613.69071 | K12: =IF('MFH-Kalkulator'!$C$6="Ein",'Miete, Cashflow, Steuern'!K11,'Miete, Cashflow, Steuern'!K10) -> 632.10143 | ... BA12: =IF('MFH-Kalkulator'!$C$6="Ein",'Miete, Cashflow, Steuern'!BA11,'Miete, Cashflow, Steuern'!BA10) -> 2187.5108
B13: + umlagefähige Kosten | D13: =Cockpit!K9 -> 111 | E13: =D13*(1+Cockpit!$H$30) -> 113.22 | F13: =E13*(1+Cockpit!$H$30) -> 115.4844 | G13: =F13*(1+Cockpit!$H$30) -> 117.79409 | H13: =G13*(1+Cockpit!$H$30) -> 120.14997 | I13: =H13*(1+Cockpit!$H$30) -> 122.55297 | J13: =I13*(1+Cockpit!$H$30) -> 125.00403 | K13: =J13*(1+Cockpit!$H$30) -> 127.50411 | L13: =K13*(1+Cockpit!$H$30) -> 130.05419 | ... BA13: =AZ13*(1+Cockpit!$H$30) -> 292.90811
B14: = Bruttokaltmiete | D14: =D12+D13 -> 640.375 | E14: =E12+E13 -> 642.595 | F14: =F12+F13 -> 660.74065 | G14: =G12+G13 -> 679.40803 | H14: =H12+H13 -> 698.61233 | I14: =I12+I13 -> 718.3692 | J14: =J12+J13 -> 738.69474 | K14: =K12+K13 -> 759.60554 | ... BA14: =BA12+BA13 -> 2480.4189
B17: Cashflow pro Monat
D18: =D7 -> 2024 | E18: =E7 -> 2025 | F18: =F7 -> 2026 | G18: =G7 -> 2027 | H18: =H7 -> 2028 | I18: =I7 -> 2029 | J18: =J7 -> 2030 | K18: =K7 -> 2031 | ... BA18: =BA7 -> 2073
B19: Bruttokaltmiete | D19: =D14 -> 640.375 | E19: =E14 -> 642.595 | F19: =F14 -> 660.74065 | G19: =G14 -> 679.40803 | H19: =H14 -> 698.61233 | I19: =I14 -> 718.3692 | J19: =J14 -> 738.69474 | K19: =K14 -> 759.60554 | ... BA19: =BA14 -> 2480.4189
B20: - Bewirtschaftungskosten ohne eigene Rücklagen | D20: =-(Cockpit!K12-Cockpit!K27-Cockpit!K28) -> -156 | E20: =D20*(1+Cockpit!$H$30) -> -159.12 | F20: =E20*(1+Cockpit!$H$30) -> -162.3024 | G20: =F20*(1+Cockpit!$H$30) -> -165.54845 | H20: =G20*(1+Cockpit!$H$30) -> -168.85942 | I20: =H20*(1+Cockpit!$H$30) -> -172.23661 | J20: =I20*(1+Cockpit!$H$30) -> -175.68134 | K20: =J20*(1+Cockpit!$H$30) -> -179.19496 | L20: =K20*(1+Cockpit!$H$30) -> -182.77886 | ... BA20: =AZ20*(1+Cockpit!$H$30) -> -411.65464
B21: - Eigene Instandhaltungsrücklage | D21: =-Cockpit!K27 -> -35.291667 | E21: =D21*(1+Cockpit!$H$30) -> -35.9975 | F21: =E21*(1+Cockpit!$H$30) -> -36.71745 | G21: =F21*(1+Cockpit!$H$30) -> -37.451799 | H21: =G21*(1+Cockpit!$H$30) -> -38.200835 | I21: =H21*(1+Cockpit!$H$30) -> -38.964852 | J21: =I21*(1+Cockpit!$H$30) -> -39.744149 | K21: =J21*(1+Cockpit!$H$30) -> -40.539032 | L21: =K21*(1+Cockpit!$H$30) -> -41.349812 | ... BA21: =AZ21*(1+Cockpit!$H$30) -> -93.128066
B22: - Rücklage Kalkulatorischer Mietausfall | D22: =-Cockpit!K28 -> -19.21125 | E22: =-Cockpit!$H$25*'Miete, Cashflow, Steuern'!E14 -> -19.27785 | F22: =-Cockpit!$H$25*'Miete, Cashflow, Steuern'!F14 -> -19.82222 | G22: =-Cockpit!$H$25*'Miete, Cashflow, Steuern'!G14 -> -20.382241 | H22: =-Cockpit!$H$25*'Miete, Cashflow, Steuern'!H14 -> -20.95837 | I22: =-Cockpit!$H$25*'Miete, Cashflow, Steuern'!I14 -> -21.551076 | J22: =-Cockpit!$H$25*'Miete, Cashflow, Steuern'!J14 -> -22.160842 | K22: =-Cockpit!$H$25*'Miete, Cashflow, Steuern'!K14 -> -22.788166 | L22: =-Cockpit!$H$25*'Miete, Cashflow, Steuern'!L14 -> -23.43356 | ... BA22: =-Cockpit!$H$25*'Miete, Cashflow, Steuern'!BA14 -> -74.412568
B23: Summe Bewirtschaftungskosten | D23: =D20+D21+D22 -> -210.50292 | E23: =E20+E21+E22 -> -214.39535 | F23: =F20+F21+F22 -> -218.84207 | G23: =G20+G21+G22 -> -223.38249 | H23: =H20+H21+H22 -> -228.01862 | I23: =I20+I21+I22 -> -232.75253 | J23: =J20+J21+J22 -> -237.58633 | K23: =K20+K21+K22 -> -242.52216 | ... BA23: =BA20+BA21+BA22 -> -579.19527
B24: - Zinsen | D24: =-'Wert, AfA, Darlehen'!D110/12 -> -308.33333 | E24: =-'Wert, AfA, Darlehen'!E110/12 -> -301.24167 | F24: =-'Wert, AfA, Darlehen'!F110/12 -> -263.05427 | G24: =-'Wert, AfA, Darlehen'!G110/12 -> -254.28728 | H24: =-'Wert, AfA, Darlehen'!H110/12 -> -245.19591 | I24: =-'Wert, AfA, Darlehen'!I110/12 -> -235.76816 | J24: =-'Wert, AfA, Darlehen'!J110/12 -> -225.99158 | K24: =-'Wert, AfA, Darlehen'!K110/12 -> -215.85327 | ... BA24: =-'Wert, AfA, Darlehen'!BA110/12 -> 0
B25: - Tilgung | C25: - Tilgung | D25: =-'Wert, AfA, Darlehen'!D114/12 -> -191.66667 | E25: =-'Wert, AfA, Darlehen'!E114/12 -> -198.75833 | F25: =-'Wert, AfA, Darlehen'!F114/12 -> -236.94573 | G25: =-'Wert, AfA, Darlehen'!G114/12 -> -245.71272 | H25: =-'Wert, AfA, Darlehen'!H114/12 -> -254.80409 | I25: =-'Wert, AfA, Darlehen'!I114/12 -> -264.23184 | J25: =-'Wert, AfA, Darlehen'!J114/12 -> -274.00842 | K25: =-'Wert, AfA, Darlehen'!K114/12 -> -284.14673 | ... BA25: =-'Wert, AfA, Darlehen'!BA114/12 -> 0
B26: = Cashflow operativ | C26: = Cashflow operativ | D26: =D19+D23+D24+D25 -> -70.127917 | E26: =E19+E23+E24+E25 -> -71.80035 | F26: =F19+F23+F24+F25 -> -58.101419 | G26: =G19+G23+G24+G25 -> -43.974462 | H26: =H19+H23+H24+H25 -> -29.406296 | I26: =I19+I23+I24+I25 -> -14.383337 | J26: =J19+J23+J24+J25 -> 1.1084133 | K26: =K19+K23+K24+K25 -> 17.083381 | ... BA26: =BA19+BA23+BA24+BA25 -> 1901.2237
B27: - Steuern | C27: - Steuern | D27: =-D43 -> -29.279167 | E27: =-E43 -> -31.755833 | F27: =-F43 -> -53.01609 | G27: =-G43 -> -62.691418 | H27: =-H43 -> -72.685298 | I27: =-I43 -> -83.008271 | J27: =-J43 -> -93.671228 | K27: =-K43 -> -104.68542 | ... BA27: =-BA43 -> -786.36822
B28: = Cashflow nach Steuern | D28: =D26+D27 -> -99.407083 | E28: =E26+E27 -> -103.55618 | F28: =F26+F27 -> -111.11751 | G28: =G26+G27 -> -106.66588 | H28: =H26+H27 -> -102.09159 | I28: =I26+I27 -> -97.391609 | J28: =J26+J27 -> -92.562815 | K28: =K26+K27 -> -87.602042 | ... BA28: =BA26+BA27 -> 1114.8555
B30: Break Even Rechnung
D31: =D7 -> 2024 | E31: =E7 -> 2025 | F31: =F7 -> 2026 | G31: =G7 -> 2027 | H31: =H7 -> 2028 | I31: =I7 -> 2029 | J31: =J7 -> 2030 | K31: =K7 -> 2031 | ... BA31: =BA7 -> 2073
B32: Kumulierter Cashflow am Jahresende | D32: =12*D28 -> -1192.885 | E32: =D32+12*E28 -> -2435.5592 | F32: =E32+12*F28 -> -3768.9693 | G32: =F32+12*G28 -> -5048.9599 | H32: =G32+12*H28 -> -6274.059 | I32: =H32+12*I28 -> -7442.7583 | J32: =I32+12*J28 -> -8553.5121 | K32: =J32+12*K28 -> -9604.7366 | L32: =K32+12*L28 -> -10594.809 | ... BA32: =AZ32+12*BA28 -> 237506.49
B33: Kumulierter Cashflow inkl. Eigenkapitaleinsatz | D33: =-Cockpit!$N$10+D32 -> -39517.885 | E33: =-Cockpit!$N$10+E32 -> -40760.559 | F33: =-Cockpit!$N$10+F32 -> -42093.969 | G33: =-Cockpit!$N$10+G32 -> -43373.96 | H33: =-Cockpit!$N$10+H32 -> -44599.059 | I33: =-Cockpit!$N$10+I32 -> -45767.758 | J33: =-Cockpit!$N$10+J32 -> -46878.512 | K33: =-Cockpit!$N$10+K32 -> -47929.737 | ... BA33: =-Cockpit!$N$10+BA32 -> 199181.49
B35: Nebenrechnung Steuer pro Monat
D36: =D7 -> 2024 | E36: =E7 -> 2025 | F36: =F7 -> 2026 | G36: =G7 -> 2027 | H36: =H7 -> 2028 | I36: =I7 -> 2029 | J36: =J7 -> 2030 | K36: =K7 -> 2031 | ... BA36: =BA7 -> 2073
B37: Bruttokaltmiete | D37: =D14 -> 640.375 | E37: =E14 -> 642.595 | F37: =F14 -> 660.74065 | G37: =G14 -> 679.40803 | H37: =H14 -> 698.61233 | I37: =I14 -> 718.3692 | J37: =J14 -> 738.69474 | K37: =K14 -> 759.60554 | ... BA37: =BA14 -> 2480.4189
B38: - Bewirtschaftungskosten ohne eigene Rücklagen | D38: =D23-D21-D22 -> -156 | E38: =E23-E21-E22 -> -159.12 | F38: =F23-F21-F22 -> -162.3024 | G38: =G23-G21-G22 -> -165.54845 | H38: =H23-H21-H22 -> -168.85942 | I38: =I23-I21-I22 -> -172.23661 | J38: =J23-J21-J22 -> -175.68134 | K38: =K23-K21-K22 -> -179.19496 | ... BA38: =BA23-BA21-BA22 -> -411.65464
B39: - Zinsen | D39: =-'Wert, AfA, Darlehen'!D110/12 -> -308.33333 | E39: =-'Wert, AfA, Darlehen'!E110/12 -> -301.24167 | F39: =-'Wert, AfA, Darlehen'!F110/12 -> -263.05427 | G39: =-'Wert, AfA, Darlehen'!G110/12 -> -254.28728 | H39: =-'Wert, AfA, Darlehen'!H110/12 -> -245.19591 | I39: =-'Wert, AfA, Darlehen'!I110/12 -> -235.76816 | J39: =-'Wert, AfA, Darlehen'!J110/12 -> -225.99158 | K39: =-'Wert, AfA, Darlehen'!K110/12 -> -215.85327 | ... BA39: =-'Wert, AfA, Darlehen'!BA110/12 -> 0
B40: - Abschreibung für Abnutzung (AfA) | D40: =-'Wert, AfA, Darlehen'!D19-'Wert, AfA, Darlehen'!D24-IF(Cockpit!E32="Abziehen",'Wert, AfA, Darlehen'!D34,'Wert, AfA, Darlehen'!D34-'Wert, AfA, Darlehen'!D28/12) -> -102.84375 | E40: =-'Wert, AfA, Darlehen'!E19-'Wert, AfA, Darlehen'!E24-'Wert, AfA, Darlehen'!E34 -> -102.84375 | F40: =-'Wert, AfA, Darlehen'!F19-'Wert, AfA, Darlehen'!F24-'Wert, AfA, Darlehen'!F34 -> -102.84375 | G40: =-'Wert, AfA, Darlehen'!G19-'Wert, AfA, Darlehen'!G24-'Wert, AfA, Darlehen'!G34 -> -102.84375 | H40: =-'Wert, AfA, Darlehen'!H19-'Wert, AfA, Darlehen'!H24-'Wert, AfA, Darlehen'!H34 -> -102.84375 | I40: =-'Wert, AfA, Darlehen'!I19-'Wert, AfA, Darlehen'!I24-'Wert, AfA, Darlehen'!I34 -> -102.84375 | J40: =-'Wert, AfA, Darlehen'!J19-'Wert, AfA, Darlehen'!J24-'Wert, AfA, Darlehen'!J34 -> -102.84375 | K40: =-'Wert, AfA, Darlehen'!K19-'Wert, AfA, Darlehen'!K24-'Wert, AfA, Darlehen'!K34 -> -102.84375 | L40: =-'Wert, AfA, Darlehen'!L19-'Wert, AfA, Darlehen'!L24-'Wert, AfA, Darlehen'!L34 -> -102.84375 | ... BA40: =-'Wert, AfA, Darlehen'!BA19-'Wert, AfA, Darlehen'!BA24-'Wert, AfA, Darlehen'!BA34 -> -102.84375
B41: = zu versteuernder Cashflow | D41: =SUM(D37:D40) -> 73.197917 | E41: =SUM(E37:E40) -> 79.389583 | F41: =SUM(F37:F40) -> 132.54023 | G41: =SUM(G37:G40) -> 156.72854 | H41: =SUM(H37:H40) -> 181.71325 | I41: =SUM(I37:I40) -> 207.52068 | J41: =SUM(J37:J40) -> 234.17807 | K41: =SUM(K37:K40) -> 261.71356 | ... BA41: =SUM(BA37:BA40) -> 1965.9206
B42: * persönlicher Grenzsteuersatz | D42: =Cockpit!Q33 -> 0.4 | E42: 0.4 | F42: =E42 -> 0.4 | G42: =F42 -> 0.4 | H42: =G42 -> 0.4 | I42: =H42 -> 0.4 | J42: =I42 -> 0.4 | K42: =J42 -> 0.4 | L42: =K42 -> 0.4 | M42: =L42 -> 0.4 | ... BA42: =AZ42 -> 0.4
B43: = Steuern | D43: =D42*D41 -> 29.279167 | E43: =E42*E41 -> 31.755833 | F43: =F42*F41 -> 53.01609 | G43: =G42*G41 -> 62.691418 | H43: =H42*H41 -> 72.685298 | I43: =I42*I41 -> 83.008271 | J43: =J42*J41 -> 93.671228 | K43: =K42*K41 -> 104.68542 | ... BA43: =BA42*BA41 -> 786.36822
B45: Keine Gewähr für die Richtigkeit der Angaben. Dieses Tool ersetzt keine fundierte Rechts-, Steuer- oder Finanzberatung. Mehr Details hier.

Sheet Wert, AfA, Darlehen
B1: zurück zum Cockpit | E1: Wert, Abschreibung und Darlehen | J1: zu Miete, Cashflow, Steuern wechseln
B6: Wertentwicklung
B7: € | D7: =YEAR(Cockpit!C10) -> 2024 | E7: =D7+1 -> 2025 | F7: =E7+1 -> 2026 | G7: =F7+1 -> 2027 | H7: =G7+1 -> 2028 | I7: =H7+1 -> 2029 | J7: =I7+1 -> 2030 | K7: =J7+1 -> 2031 | L7: =K7+1 -> 2032 | ... BA7: =AZ7+1 -> 2073
B8: Wert der Immobilie (Jahresanfang) | D8: =Cockpit!D14+Cockpit!E30 -> 125000 | E8: =D12 -> 127500 | F8: =E12 -> 130050 | G8: =F12 -> 132651 | H8: =G12 -> 135304.02 | I8: =H12 -> 138010.1 | J8: =I12 -> 140770.3 | K8: =J12 -> 143585.71 | L8: =K12 -> 146457.42 | ... BA8: =AZ12 -> 329851.47
B9: Nettovermögen (Wert - Restschuld) (Jahresanfang) | D9: =D8-'Wert, AfA, Darlehen'!D106 -> 25000 | E9: =E8-'Wert, AfA, Darlehen'!E106 -> 29800 | F9: =F8-'Wert, AfA, Darlehen'!F106 -> 44735.1 | G9: =G8-'Wert, AfA, Darlehen'!G106 -> 50179.449 | H9: =H8-'Wert, AfA, Darlehen'!H106 -> 55781.021 | I9: =I8-'Wert, AfA, Darlehen'!I106 -> 61544.751 | J9: =J8-'Wert, AfA, Darlehen'!J106 -> 67475.735 | K9: =K8-'Wert, AfA, Darlehen'!K106 -> 73579.242 | ... BA9: =BA8-'Wert, AfA, Darlehen'!BA106 -> 329851.47
B10: Wertentwicklung im Jahr | D10: =Cockpit!$H$32 -> 0.02 | E10: =D10 -> 0.02 | F10: =E10 -> 0.02 | G10: =F10 -> 0.02 | H10: =G10 -> 0.02 | I10: =H10 -> 0.02 | J10: =I10 -> 0.02 | K10: =J10 -> 0.02 | L10: =K10 -> 0.02 | ... BA10: =AZ10 -> 0.02
B11: Wertentwicklung im Jahr | D11: =D8*D10 -> 2500 | E11: =E8*E10 -> 2550 | F11: =F8*F10 -> 2601 | G11: =G8*G10 -> 2653.02 | H11: =H8*H10 -> 2706.0804 | I11: =I8*I10 -> 2760.202 | J11: =J8*J10 -> 2815.406 | K11: =K8*K10 -> 2871.7142 | ... BA11: =BA8*BA10 -> 6597.0295
B12: Wert der Immobilie (Jahresende) | D12: =D8+D11 -> 127500 | E12: =E8+E11 -> 130050 | F12: =F8+F11 -> 132651 | G12: =G8+G11 -> 135304.02 | H12: =H8+H11 -> 138010.1 | I12: =I8+I11 -> 140770.3 | J12: =J8+J11 -> 143585.71 | K12: =K8+K11 -> 146457.42 | ... BA12: =BA8+BA11 -> 336448.5
B14: Abschreibung Regulär
B15: € | D15: ='Miete, Cashflow, Steuern'!D7 -> 2024 | E15: ='Miete, Cashflow, Steuern'!E7 -> 2025 | F15: ='Miete, Cashflow, Steuern'!F7 -> 2026 | G15: ='Miete, Cashflow, Steuern'!G7 -> 2027 | H15: ='Miete, Cashflow, Steuern'!H7 -> 2028 | I15: ='Miete, Cashflow, Steuern'!I7 -> 2029 | J15: ='Miete, Cashflow, Steuern'!J7 -> 2030 | K15: ='Miete, Cashflow, Steuern'!K7 -> 2031 | ... BA15: ='Miete, Cashflow, Steuern'!BA7 -> 2073
B16: = Basis für langfristige Abschreibung | D16: =Cockpit!H22 -> 82275 | E16: =D16 -> 82275 | F16: =E16 -> 82275 | G16: =F16 -> 82275 | H16: =G16 -> 82275 | I16: =H16 -> 82275 | J16: =I16 -> 82275 | K16: =J16 -> 82275 | L16: =K16 -> 82275 | ... BA16: =AZ16 -> 82275
B17: * Abschreibungssatz pro Jahr | D17: =Cockpit!H20 -> 0.015 | E17: =D17 -> 0.015 | F17: =E17 -> 0.015 | G17: =F17 -> 0.015 | H17: =G17 -> 0.015 | I17: =H17 -> 0.015 | J17: =I17 -> 0.015 | K17: =J17 -> 0.015 | L17: =K17 -> 0.015 | ... BA17: =AZ17 -> 0.015
B18: = Abschreibung pro Jahr | D18: =D17*D16 -> 1234.125 | E18: =MIN(E17*E16,E16-D20) -> 1234.125 | F18: =MIN(F17*F16,F16-E20) -> 1234.125 | G18: =MIN(G17*G16,G16-F20) -> 1234.125 | H18: =MIN(H17*H16,H16-G20) -> 1234.125 | I18: =MIN(I17*I16,I16-H20) -> 1234.125 | J18: =MIN(J17*J16,J16-I20) -> 1234.125 | K18: =MIN(K17*K16,K16-J20) -> 1234.125 | L18: =MIN(L17*L16,L16-K20) -> 1234.125 | ... BA18: =MIN(BA17*BA16,BA16-AZ20) -> 1234.125
B19: = pro Monat | D19: =D18/12 -> 102.84375 | E19: =E18/12 -> 102.84375 | F19: =F18/12 -> 102.84375 | G19: =G18/12 -> 102.84375 | H19: =H18/12 -> 102.84375 | I19: =I18/12 -> 102.84375 | J19: =J18/12 -> 102.84375 | K19: =K18/12 -> 102.84375 | ... BA19: =BA18/12 -> 102.84375
B20: Kumulierte Abschreibung Jahresende | D20: =D18 -> 1234.125 | E20: =D20+E18 -> 2468.25 | F20: =E20+F18 -> 3702.375 | G20: =F20+G18 -> 4936.5 | H20: =G20+H18 -> 6170.625 | I20: =H20+I18 -> 7404.75 | J20: =I20+J18 -> 8638.875 | K20: =J20+K18 -> 9873 | L20: =K20+L18 -> 11107.125 | ... BA20: =AZ20+BA18 -> 61706.25
B22: Abschreibung Denkmal
B23: € | D23: =D7 -> 2024 | E23: =E7 -> 2025 | F23: =F7 -> 2026 | G23: =G7 -> 2027 | H23: =H7 -> 2028 | I23: =I7 -> 2029 | J23: =J7 -> 2030 | K23: =K7 -> 2031 | ... BA23: =BA7 -> 2073
B24: = pro Monat | D24: 0 | E24: 0 | F24: 0 | G24: 0 | H24: 0 | I24: 0 | J24: 0 | K24: 0 | L24: 0 | M24: 0 | N24: 0 | O24: 0 | P24: 0 | Q24: 0 | R24: 0 | S24: 0 | T24: 0 | U24: 0 | V24: 0 | W24: 0 | X24: 0 | Y24: 0 | Z24: 0 | AA24: 0 | AB24: 0 | AC24: 0 | AD24: 0 | AE24: 0 | AF24: 0 | AG24: 0 | AH24: 0 | AI24: 0 | AJ24: 0 | AK24: 0 | AL24: 0 | AM24: 0 | AN24: 0 | AO24: 0 | AP24: 0 | AQ24: 0 | AR24: 0 | AS24: 0 | AT24: 0 | AU24: 0 | AV24: 0 | AW24: 0 | AX24: 0 | AY24: 0 | AZ24: 0 | BA24: 0
B26: Abschreibung Investitionen
B27: € | D27: =D15 -> 2024 | E27: =E15 -> 2025 | F27: =F15 -> 2026 | G27: =G15 -> 2027 | H27: =H15 -> 2028 | I27: =I15 -> 2029 | J27: =J15 -> 2030 | K27: =K15 -> 2031 | ... BA27: =BA15 -> 2073
B28: =CONCATENATE("Sofort abzugfsähig (",SUMIF(Cockpit!D26:D29,"Sofort",Cockpit!C26:C29)," €)") -> Sofort abzugfsähig (0 €) | D28: =IF(Cockpit!E32="Abziehen",SUMIF(Cockpit!D26:D29,"Sofort",Cockpit!C26:C29),0) -> 0 | E28: 0 | F28: 0 | G28: 0 | H28: 0 | I28: 0 | J28: 0 | K28: 0 | L28: 0 | M28: 0 | N28: 0 | O28: 0 | P28: 0 | Q28: 0 | R28: 0 | S28: 0 | T28: 0 | U28: 0 | V28: 0 | W28: 0 | X28: 0 | Y28: 0 | Z28: 0 | AA28: 0 | AB28: 0 | AC28: 0 | AD28: 0 | AE28: 0 | AF28: 0 | AG28: 0 | AH28: 0 | AI28: 0 | AJ28: 0 | AK28: 0 | AL28: 0 | AM28: 0 | AN28: 0 | AO28: 0 | AP28: 0 | AQ28: 0 | AR28: 0 | AS28: 0 | AT28: 0 | AU28: 0 | AV28: 0 | AW28: 0 | AX28: 0 | AY28: 0 | AZ28: 0 | BA28: 0
B29: =CONCATENATE("Abschreibung über 10 Jahre (",SUMIF(Cockpit!D26:D29,"10 Jahre",Cockpit!C26:C29)," €)") -> Abschreibung über 10 Jahre (0 €) | D29: =SUMIF(Cockpit!D26:D29,"10 Jahre",Cockpit!C26:C29)/10 -> 0 | E29: =D29 -> 0 | F29: =E29 -> 0 | G29: =F29 -> 0 | H29: =G29 -> 0 | I29: =H29 -> 0 | J29: =I29 -> 0 | K29: =J29 -> 0 | L29: =K29 -> 0 | M29: =L29 -> 0 | N29: 0 | O29: 0 | P29: 0 | Q29: 0 | R29: 0 | S29: 0 | T29: 0 | U29: 0 | V29: 0 | W29: 0 | X29: 0 | Y29: 0 | Z29: 0 | AA29: 0 | AB29: 0 | AC29: 0 | AD29: 0 | AE29: 0 | AF29: 0 | AG29: 0 | AH29: 0 | AI29: 0 | AJ29: 0 | AK29: 0 | AL29: 0 | AM29: 0 | AN29: 0 | AO29: 0 | AP29: 0 | AQ29: 0 | AR29: 0 | AS29: 0 | AT29: 0 | AU29: 0 | AV29: 0 | AW29: 0 | AX29: 0 | AY29: 0 | AZ29: 0 | BA29: 0
B30: =CONCATENATE("Abschreibung über 15 Jahre (",SUMIF(Cockpit!D26:D29,"15 Jahre",Cockpit!C26:C29)," €)") -> Abschreibung über 15 Jahre (0 €) | D30: =SUMIF(Cockpit!D26:D29,"15 Jahre",Cockpit!C26:C29)/15 -> 0 | E30: =D30 -> 0 | F30: =E30 -> 0 | G30: =F30 -> 0 | H30: =G30 -> 0 | I30: =H30 -> 0 | J30: =I30 -> 0 | K30: =J30 -> 0 | L30: =K30 -> 0 | ... R30: =Q30 -> 0 | S30: 0 | T30: 0 | U30: 0 | V30: 0 | W30: 0 | X30: 0 | Y30: 0 | Z30: 0 | AA30: 0 | AB30: 0 | AC30: 0 | AD30: 0 | AE30: 0 | AF30: 0 | AG30: 0 | AH30: 0 | AI30: 0 | AJ30: 0 | AK30: 0 | AL30: 0 | AM30: 0 | AN30: 0 | AO30: 0 | AP30: 0 | AQ30: 0 | AR30: 0 | AS30: 0 | AT30: 0 | AU30: 0 | AV30: 0 | AW30: 0 | AX30: 0 | AY30: 0 | AZ30: 0 | BA30: 0
B31: =CONCATENATE("Abschreibung über 50 Jahre (",SUMIF(Cockpit!D26:D29,"50 Jahre",Cockpit!C26:C29)," €)") -> Abschreibung über 50 Jahre (0 €) | D31: =SUMIF(Cockpit!D26:D29,"50 Jahre",Cockpit!C26:C29)/50 -> 0 | E31: =D31 -> 0 | F31: =E31 -> 0 | G31: =F31 -> 0 | H31: =G31 -> 0 | I31: =H31 -> 0 | J31: =I31 -> 0 | K31: =J31 -> 0 | L31: =K31 -> 0 | ... BA31: =AZ31 -> 0
B32: =CONCATENATE("Abschreibung über 67 Jahre (",SUMIF(Cockpit!D26:D29,"67 Jahre",Cockpit!C26:C29)," €)") -> Abschreibung über 67 Jahre (0 €) | D32: =SUMIF(Cockpit!D26:D29,"67 Jahre",Cockpit!C26:C29)/67 -> 0 | E32: =D32 -> 0 | F32: =E32 -> 0 | G32: =F32 -> 0 | H32: =G32 -> 0 | I32: =H32 -> 0 | J32: =I32 -> 0 | K32: =J32 -> 0 | L32: =K32 -> 0 | ... BA32: =AZ32 -> 0
B33: Summe pro Jahr | D33: =SUM(D28:D32) -> 0 | E33: =SUM(E28:E32) -> 0 | F33: =SUM(F28:F32) -> 0 | G33: =SUM(G28:G32) -> 0 | H33: =SUM(H28:H32) -> 0 | I33: =SUM(I28:I32) -> 0 | J33: =SUM(J28:J32) -> 0 | K33: =SUM(K28:K32) -> 0 | ... BA33: =SUM(BA28:BA32) -> 0
B34: = pro Monat | D34: =D33/12 -> 0 | E34: =E33/12 -> 0 | F34: =F33/12 -> 0 | G34: =G33/12 -> 0 | H34: =H33/12 -> 0 | I34: =I33/12 -> 0 | J34: =J33/12 -> 0 | K34: =K33/12 -> 0 | ... BA34: =BA33/12 -> 0
B36: Darlehen I
B37: € | D37: =D$7 -> 2024 | E37: =E$7 -> 2025 | F37: =F$7 -> 2026 | G37: =G$7 -> 2027 | H37: =H$7 -> 2028 | I37: =I$7 -> 2029 | J37: =J$7 -> 2030 | K37: =K$7 -> 2031 | ... BA37: =BA$7 -> 2073
B38: Zinsänderung
B39: Gültiger Zinssatz | D39: =Cockpit!N18 -> 0.037 | E39: =IF(E38<>"",E38,D39) -> 0.037 | F39: =IF(F38<>"",F38,E39) -> 0.037 | G39: =IF(G38<>"",G38,F39) -> 0.037 | H39: =IF(H38<>"",H38,G39) -> 0.037 | I39: =IF(I38<>"",I38,H39) -> 0.037 | J39: =IF(J38<>"",J38,I39) -> 0.037 | K39: =IF(K38<>"",K38,J39) -> 0.037 | L39: =IF(L38<>"",L38,K39) -> 0.037 | ... BA39: =IF(BA38<>"",BA38,AZ39) -> 0.037
B41: Restschuld Periodenbeginn | D41: =Cockpit!N17 -> 100000 | E41: =D50 -> 97700 | F41: =E50 -> 85314.9 | G41: =F50 -> 82471.551 | H41: =G50 -> 79522.999 | I41: =H50 -> 76465.35 | J41: =I50 -> 73294.568 | K41: =J50 -> 70006.467 | L41: =K50 -> 66596.706 | ... BA41: =AZ50 -> 0
B42: Zinsen | D42: =D39*D41 -> 3700 | E42: =E39*E41 -> 3614.9 | F42: =F39*F41 -> 3156.6513 | G42: =G39*G41 -> 3051.4474 | H42: =H39*H41 -> 2942.351 | I42: =I39*I41 -> 2829.2179 | J42: =J39*J41 -> 2711.899 | K42: =K39*K41 -> 2590.2393 | ... BA42: =BA39*BA41 -> 0
B44: Neue Soll-Tilgung
B45: Effektive Tilgung | D45: =Cockpit!$N$19*D41 -> 2300 | E45: =MIN(D50,IF(E44<>"",E44,MAX(D48-E42,0))) -> 2385.1 | F45: =MIN(E50,IF(F44<>"",F44,MAX(E48-F42,0))) -> 2843.3487 | G45: =MIN(F50,IF(G44<>"",G44,MAX(F48-G42,0))) -> 2948.5526 | H45: =MIN(G50,IF(H44<>"",H44,MAX(G48-H42,0))) -> 3057.649 | I45: =MIN(H50,IF(I44<>"",I44,MAX(H48-I42,0))) -> 3170.7821 | J45: =MIN(I50,IF(J44<>"",J44,MAX(I48-J42,0))) -> 3288.101 | K45: =MIN(J50,IF(K44<>"",K44,MAX(J48-K42,0))) -> 3409.7607 | L45: =MIN(K50,IF(L44<>"",L44,MAX(K48-L42,0))) -> 3535.9219 | ... BA45: =MIN(AZ50,IF(BA44<>"",BA44,MAX(AZ48-BA42,0))) -> 0
B46: entspricht % der Restschuld | D46: =IF(D41>0,D45/D41,) -> 0.023 | E46: =IF(E41>0,E45/E41,) -> 0.024412487 | F46: =IF(F41>0,F45/F41,) -> 0.033327692 | G46: =IF(G41>0,G45/G41,) -> 0.03575236 | H46: =IF(H41>0,H45/H41,) -> 0.038449871 | I46: =IF(I41>0,I45/I41,) -> 0.041466914 | J46: =IF(J41>0,J45/J41,) -> 0.044861456 | K46: =IF(K41>0,K45/K41,) -> 0.048706368 | ... BA46: =IF(BA41>0,BA45/BA41,) -> 0
B48: Annuität | D48: =D42+D45 -> 6000 | E48: =E42+E45 -> 6000 | F48: =F42+F45 -> 6000 | G48: =G42+G45 -> 6000 | H48: =H42+H45 -> 6000 | I48: =I42+I45 -> 6000 | J48: =J42+J45 -> 6000 | K48: =K42+K45 -> 6000 | ... BA48: =BA42+BA45 -> 0
B49: Einmalige Sondertilgung | E49: 10000
B50: Restschuld Periodenende | D50: =MAX(D41-D45-D49,0) -> 97700 | E50: =MAX(E41-E45-E49,0) -> 85314.9 | F50: =MAX(F41-F45-F49,0) -> 82471.551 | G50: =MAX(G41-G45-G49,0) -> 79522.999 | H50: =MAX(H41-H45-H49,0) -> 76465.35 | I50: =MAX(I41-I45-I49,0) -> 73294.568 | J50: =MAX(J41-J45-J49,0) -> 70006.467 | K50: =MAX(K41-K45-K49,0) -> 66596.706 | ... BA50: =MAX(BA41-BA45-BA49,0) -> 0
B51: Kapitaldienst pro Monat | D51: =D48/12 -> 500 | E51: =E48/12 -> 500 | F51: =F48/12 -> 500 | G51: =G48/12 -> 500 | H51: =H48/12 -> 500 | I51: =I48/12 -> 500 | J51: =J48/12 -> 500 | K51: =K48/12 -> 500 | ... BA51: =BA48/12 -> 0
...

Sheet Szenarien
C1: zurück zum Cockpit | P1: Szenarien-Vergleich
B6: Sprünge | U6: Sprünge
B7: 5000 | C7: Darlehen I % Kaufpreis | D7: Darlehen I Summe | E7: Darlehen I Zinssatz | F7: Darlehen I Tilgung | G7: Kaltmiete | H7: Bruttokaltmiete | I7: Bewirtschaftungskosten | J7: Zinsen | K7: Tilgung | L7: CF operativ | M7: Hausgeld und weitere Kosten | N7: AfA | O7: Steuern | P7: Cashflow nach Steuern (Monat) | R7: Kaufpreis | S7: Darlehen I % Kaufpreis | T7: Darlehen I Summe | U7: 0.001 | V7: Darlehen I Tilgung | W7: Kaltmiete | X7: Bruttokaltmiete | Y7: Bewirtschaftungskosten | Z7: Zinsen | AA7: Tilgung | AB7: CF operativ | AC7: Hausgeld und weitere Kosten | AD7: AfA | AE7: Steuern | AF7: Cashflow nach Steuern (Monat) | AH7: Ausgangsdaten
B8: Kaufpreis | U8: Zinssatz
B9: =B10+$B$7 -> 145000 | C9: =$AL$10 -> 0.8 | D9: =B9*C9 -> 116000 | E9: =$AL$11 -> 0.037 | F9: =$AL$12 -> 0.023 | G9: =$AL$13 -> 529.375 | H9: =G9+Cockpit!$K$9 -> 640.375 | I9: =-Cockpit!$K$12-Cockpit!$H$25*(Szenarien!G9-Szenarien!$AL$13) -> -210.50292 | J9: =Cockpit!$Q$21-E9*(D9-$D13)/12 -> -357.66667 | K9: =Cockpit!$Q$22-F9*(D9-$D13)/12 -> -222.33333 | L9: =H9+I9+J9+K9 -> -150.12792 | M9: =Cockpit!$Q$29 -> -156 | N9: =Cockpit!$Q$31-Cockpit!$H$20*Cockpit!$H$21*(1+Cockpit!$D$22)*(B9-$B13)/12 -> -119.47875 | O9: =(H9+J9+M9+N9)*Cockpit!$Q$33 -> 2.8918333 | P9: =L9-O9 -> -153.01975 | R9: =$AL$9 -> 125000 | S9: =$AL$10 -> 0.8 | T9: =R9*S9 -> 100000 | U9: =U10+$U$7 -> 0.041 | V9: =$AL$12 -> 0.023 | W9: =$AL$13 -> 529.375 | X9: =W9+Cockpit!$K$9 -> 640.375 | Y9: =-Cockpit!$K$12-Cockpit!$H$25*(Szenarien!W9-Szenarien!$AL$13) -> -210.50292 | Z9: =Cockpit!$Q$21-U9*(T9-$T$13)/12-(U9-$U$13)*$T$13/12 -> -341.66667 | AA9: =Cockpit!$Q$22-V9*(T9-$T$13)/12-(V9-$V$13)*$T$13/12 -> -191.66667 | AB9: =X9+Y9+Z9+AA9 -> -103.46125 | AC9: =Cockpit!$Q$29 -> -156 | AD9: =Cockpit!$Q$31-Cockpit!$H$20*Cockpit!$H$21*(1+Cockpit!$D$22)*(R9-$R13)/12 -> -102.84375 | AE9: =(X9+Z9+AC9+AD9)*Cockpit!$Q$33 -> 15.945833 | AF9: =AB9-AE9 -> -119.40708 | AH9: Kaufpreis | AL9: =Cockpit!D14 -> 125000
B10: =B11+$B$7 -> 140000 | C10: =$AL$10 -> 0.8 | D10: =B10*C10 -> 112000 | E10: =$AL$11 -> 0.037 | F10: =$AL$12 -> 0.023 | G10: =$AL$13 -> 529.375 | H10: =G10+Cockpit!$K$9 -> 640.375 | I10: =-Cockpit!$K$12-Cockpit!$H$25*(Szenarien!G10-Szenarien!$AL$13) -> -210.50292 | J10: =Cockpit!$Q$21-E10*(D10-$D13)/12 -> -345.33333 | K10: =Cockpit!$Q$22-F10*(D10-$D13)/12 -> -214.66667 | L10: =H10+I10+J10+K10 -> -130.12792 | M10: =Cockpit!$Q$29 -> -156 | N10: =Cockpit!$Q$31-Cockpit!$H$20*Cockpit!$H$21*(1+Cockpit!$D$22)*(B10-$B13)/12 -> -115.32 | O10: =(H10+J10+M10+N10)*Cockpit!$Q$33 -> 9.4886667 | P10: =L10-O10 -> -139.61658 | R10: =$AL$9 -> 125000 | S10: =$AL$10 -> 0.8 | T10: =R10*S10 -> 100000 | U10: =U11+$U$7 -> 0.04 | V10: =$AL$12 -> 0.023 | W10: =$AL$13 -> 529.375 | X10: =W10+Cockpit!$K$9 -> 640.375 | Y10: =-Cockpit!$K$12-Cockpit!$H$25*(Szenarien!W10-Szenarien!$AL$13) -> -210.50292 | Z10: =Cockpit!$Q$21-U10*(T10-$T$13)/12-(U10-$U$13)*$T$13/12 -> -333.33333 | AA10: =Cockpit!$Q$22-V10*(T10-$T$13)/12-(V10-$V$13)*$T$13/12 -> -191.66667 | AB10: =X10+Y10+Z10+AA10 -> -95.127917 | AC10: =Cockpit!$Q$29 -> -156 | AD10: =Cockpit!$Q$31-Cockpit!$H$20*Cockpit!$H$21*(1+Cockpit!$D$22)*(R10-$R13)/12 -> -102.84375 | AE10: =(X10+Z10+AC10+AD10)*Cockpit!$Q$33 -> 19.279167 | AF10: =AB10-AE10 -> -114.40708 | AH10: Darlehen I % Kaufpreis | AL10: =Cockpit!N17/AL9 -> 0.8
B11: =B12+$B$7 -> 135000 | C11: =$AL$10 -> 0.8 | D11: =B11*C11 -> 108000 | E11: =$AL$11 -> 0.037 | F11: =$AL$12 -> 0.023 | G11: =$AL$13 -> 529.375 | H11: =G11+Cockpit!$K$9 -> 640.375 | I11: =-Cockpit!$K$12-Cockpit!$H$25*(Szenarien!G11-Szenarien!$AL$13) -> -210.50292 | J11: =Cockpit!$Q$21-E11*(D11-$D13)/12 -> -333 | K11: =Cockpit!$Q$22-F11*(D11-$D13)/12 -> -207 | L11: =H11+I11+J11+K11 -> -110.12792 | M11: =Cockpit!$Q$29 -> -156 | N11: =Cockpit!$Q$31-Cockpit!$H$20*Cockpit!$H$21*(1+Cockpit!$D$22)*(B11-$B13)/12 -> -111.16125 | O11: =(H11+J11+M11+N11)*Cockpit!$Q$33 -> 16.0855 | P11: =L11-O11 -> -126.21342 | R11: =$AL$9 -> 125000 | S11: =$AL$10 -> 0.8 | T11: =R11*S11 -> 100000 | U11: =U12+$U$7 -> 0.039 | V11: =$AL$12 -> 0.023 | W11: =$AL$13 -> 529.375 | X11: =W11+Cockpit!$K$9 -> 640.375 | Y11: =-Cockpit!$K$12-Cockpit!$H$25*(Szenarien!W11-Szenarien!$AL$13) -> -210.50292 | Z11: =Cockpit!$Q$21-U11*(T11-$T$13)/12-(U11-$U$13)*$T$13/12 -> -325 | AA11: =Cockpit!$Q$22-V11*(T11-$T$13)/12-(V11-$V$13)*$T$13/12 -> -191.66667 | AB11: =X11+Y11+Z11+AA11 -> -86.794583 | AC11: =Cockpit!$Q$29 -> -156 | AD11: =Cockpit!$Q$31-Cockpit!$H$20*Cockpit!$H$21*(1+Cockpit!$D$22)*(R11-$R13)/12 -> -102.84375 | AE11: =(X11+Z11+AC11+AD11)*Cockpit!$Q$33 -> 22.6125 | AF11: =AB11-AE11 -> -109.40708 | AH11: Zinssatz Darlehen I | AL11: =Cockpit!N18 -> 0.037
B12: =B13+$B$7 -> 130000 | C12: =$AL$10 -> 0.8 | D12: =B12*C12 -> 104000 | E12: =$AL$11 -> 0.037 | F12: =$AL$12 -> 0.023 | G12: =$AL$13 -> 529.375 | H12: =G12+Cockpit!$K$9 -> 640.375 | I12: =-Cockpit!$K$12-Cockpit!$H$25*(Szenarien!G12-Szenarien!$AL$13) -> -210.50292 | J12: =Cockpit!$Q$21-E12*(D12-$D13)/12 -> -320.66667 | K12: =Cockpit!$Q$22-F12*(D12-$D13)/12 -> -199.33333 | L12: =H12+I12+J12+K12 -> -90.127917 | M12: =Cockpit!$Q$29 -> -156 | N12: =Cockpit!$Q$31-Cockpit!$H$20*Cockpit!$H$21*(1+Cockpit!$D$22)*(B12-$B13)/12 -> -107.0025 | O12: =(H12+J12+M12+N12)*Cockpit!$Q$33 -> 22.682333 | P12: =L12-O12 -> -112.81025 | R12: =$AL$9 -> 125000 | S12: =$AL$10 -> 0.8 | T12: =R12*S12 -> 100000 | U12: =U13+$U$7 -> 0.038 | V12: =$AL$12 -> 0.023 | W12: =$AL$13 -> 529.375 | X12: =W12+Cockpit!$K$9 -> 640.375 | Y12: =-Cockpit!$K$12-Cockpit!$H$25*(Szenarien!W12-Szenarien!$AL$13) -> -210.50292 | Z12: =Cockpit!$Q$21-U12*(T12-$T$13)/12-(U12-$U$13)*$T$13/12 -> -316.66667 | AA12: =Cockpit!$Q$22-V12*(T12-$T$13)/12-(V12-$V$13)*$T$13/12 -> -191.66667 | AB12: =X12+Y12+Z12+AA12 -> -78.46125 | AC12: =Cockpit!$Q$29 -> -156 | AD12: =Cockpit!$Q$31-Cockpit!$H$20*Cockpit!$H$21*(1+Cockpit!$D$22)*(R12-$R13)/12 -> -102.84375 | AE12: =(X12+Z12+AC12+AD12)*Cockpit!$Q$33 -> 25.945833 | AF12: =AB12-AE12 -> -104.40708 | AH12: Anfängliche Tilgung Darlehen I | AL12: =Cockpit!N19 -> 0.023
B13: =$AL$9 -> 125000 | C13: =$AL$10 -> 0.8 | D13: =B13*C13 -> 100000 | E13: =$AL$11 -> 0.037 | F13: =$AL$12 -> 0.023 | G13: =$AL$13 -> 529.375 | H13: =G13+Cockpit!$K$9 -> 640.375 | I13: =-Cockpit!$K$12-Cockpit!$H$25*(Szenarien!G13-Szenarien!$AL$13) -> -210.50292 | J13: =Cockpit!$Q$21-E13*(D13-$D13)/12 -> -308.33333 | K13: =Cockpit!$Q$22-F13*(D13-$D13)/12 -> -191.66667 | L13: =H13+I13+J13+K13 -> -70.127917 | M13: =Cockpit!$Q$29 -> -156 | N13: =Cockpit!$Q$31-Cockpit!$H$20*Cockpit!$H$21*(1+Cockpit!$D$22)*(B13-$B13)/12 -> -102.84375 | O13: =(H13+J13+M13+N13)*Cockpit!$Q$33 -> 29.279167 | P13: =L13-O13 -> -99.407083 | R13: =$AL$9 -> 125000 | S13: =$AL$10 -> 0.8 | T13: =R13*S13 -> 100000 | U13: =$AL$11 -> 0.037 | V13: =$AL$12 -> 0.023 | W13: =$AL$13 -> 529.375 | X13: =W13+Cockpit!$K$9 -> 640.375 | Y13: =-Cockpit!$K$12-Cockpit!$H$25*(Szenarien!W13-Szenarien!$AL$13) -> -210.50292 | Z13: =Cockpit!$Q$21-U13*(T13-$T$13)/12-(U13-$U$13)*$T$13/12 -> -308.33333 | AA13: =Cockpit!$Q$22-V13*(T13-$T$13)/12-(V13-$V$13)*$T$13/12 -> -191.66667 | AB13: =X13+Y13+Z13+AA13 -> -70.127917 | AC13: =Cockpit!$Q$29 -> -156 | AD13: =Cockpit!$Q$31-Cockpit!$H$20*Cockpit!$H$21*(1+Cockpit!$D$22)*(R13-$R13)/12 -> -102.84375 | AE13: =(X13+Z13+AC13+AD13)*Cockpit!$Q$33 -> 29.279167 | AF13: =AB13-AE13 -> -99.407083 | AH13: Nettokaltmiete | AL13: =Cockpit!H15 -> 529.375
B14: =B13-$B$7 -> 120000 | C14: =$AL$10 -> 0.8 | D14: =B14*C14 -> 96000 | E14: =$AL$11 -> 0.037 | F14: =$AL$12 -> 0.023 | G14: =$AL$13 -> 529.375 | H14: =G14+Cockpit!$K$9 -> 640.375 | I14: =-Cockpit!$K$12-Cockpit!$H$25*(Szenarien!G14-Szenarien!$AL$13) -> -210.50292 | J14: =Cockpit!$Q$21-E14*(D14-$D13)/12 -> -296 | K14: =Cockpit!$Q$22-F14*(D14-$D13)/12 -> -184 | L14: =H14+I14+J14+K14 -> -50.127917 | M14: =Cockpit!$Q$29 -> -156 | N14: =Cockpit!$Q$31-Cockpit!$H$20*Cockpit!$H$21*(1+Cockpit!$D$22)*(B14-$B13)/12 -> -98.685 | O14: =(H14+J14+M14+N14)*Cockpit!$Q$33 -> 35.876 | P14: =L14-O14 -> -86.003917 | R14: =$AL$9 -> 125000 | S14: =$AL$10 -> 0.8 | T14: =R14*S14 -> 100000 | U14: =U13-$U$7 -> 0.036 | V14: =$AL$12 -> 0.023 | W14: =$AL$13 -> 529.375 | X14: =W14+Cockpit!$K$9 -> 640.375 | Y14: =-Cockpit!$K$12-Cockpit!$H$25*(Szenarien!W14-Szenarien!$AL$13) -> -210.50292 | Z14: =Cockpit!$Q$21-U14*(T14-$T$13)/12-(U14-$U$13)*$T$13/12 -> -300 | AA14: =Cockpit!$Q$22-V14*(T14-$T$13)/12-(V14-$V$13)*$T$13/12 -> -191.66667 | AB14: =X14+Y14+Z14+AA14 -> -61.794583 | AC14: =Cockpit!$Q$29 -> -156 | AD14: =Cockpit!$Q$31-Cockpit!$H$20*Cockpit!$H$21*(1+Cockpit!$D$22)*(R14-$R13)/12 -> -102.84375 | AE14: =(X14+Z14+AC14+AD14)*Cockpit!$Q$33 -> 32.6125 | AF14: =AB14-AE14 -> -94.407083
B15: =B14-$B$7 -> 115000 | C15: =$AL$10 -> 0.8 | D15: =B15*C15 -> 92000 | E15: =$AL$11 -> 0.037 | F15: =$AL$12 -> 0.023 | G15: =$AL$13 -> 529.375 | H15: =G15+Cockpit!$K$9 -> 640.375 | I15: =-Cockpit!$K$12-Cockpit!$H$25*(Szenarien!G15-Szenarien!$AL$13) -> -210.50292 | J15: =Cockpit!$Q$21-E15*(D15-$D13)/12 -> -283.66667 | K15: =Cockpit!$Q$22-F15*(D15-$D13)/12 -> -176.33333 | L15: =H15+I15+J15+K15 -> -30.127917 | M15: =Cockpit!$Q$29 -> -156 | N15: =Cockpit!$Q$31-Cockpit!$H$20*Cockpit!$H$21*(1+Cockpit!$D$22)*(B15-$B13)/12 -> -94.52625 | O15: =(H15+J15+M15+N15)*Cockpit!$Q$33 -> 42.472833 | P15: =L15-O15 -> -72.60075 | R15: =$AL$9 -> 125000 | S15: =$AL$10 -> 0.8 | T15: =R15*S15 -> 100000 | U15: =U14-$U$7 -> 0.035 | V15: =$AL$12 -> 0.023 | W15: =$AL$13 -> 529.375 | X15: =W15+Cockpit!$K$9 -> 640.375 | Y15: =-Cockpit!$K$12-Cockpit!$H$25*(Szenarien!W15-Szenarien!$AL$13) -> -210.50292 | Z15: =Cockpit!$Q$21-U15*(T15-$T$13)/12-(U15-$U$13)*$T$13/12 -> -291.66667 | AA15: =Cockpit!$Q$22-V15*(T15-$T$13)/12-(V15-$V$13)*$T$13/12 -> -191.66667 | AB15: =X15+Y15+Z15+AA15 -> -53.46125 | AC15: =Cockpit!$Q$29 -> -156 | AD15: =Cockpit!$Q$31-Cockpit!$H$20*Cockpit!$H$21*(1+Cockpit!$D$22)*(R15-$R13)/12 -> -102.84375 | AE15: =(X15+Z15+AC15+AD15)*Cockpit!$Q$33 -> 35.945833 | AF15: =AB15-AE15 -> -89.407083
B16: =B15-$B$7 -> 110000 | C16: =$AL$10 -> 0.8 | D16: =B16*C16 -> 88000 | E16: =$AL$11 -> 0.037 | F16: =$AL$12 -> 0.023 | G16: =$AL$13 -> 529.375 | H16: =G16+Cockpit!$K$9 -> 640.375 | I16: =-Cockpit!$K$12-Cockpit!$H$25*(Szenarien!G16-Szenarien!$AL$13) -> -210.50292 | J16: =Cockpit!$Q$21-E16*(D16-$D13)/12 -> -271.33333 | K16: =Cockpit!$Q$22-F16*(D16-$D13)/12 -> -168.66667 | L16: =H16+I16+J16+K16 -> -10.127917 | M16: =Cockpit!$Q$29 -> -156 | N16: =Cockpit!$Q$31-Cockpit!$H$20*Cockpit!$H$21*(1+Cockpit!$D$22)*(B16-$B13)/12 -> -90.3675 | O16: =(H16+J16+M16+N16)*Cockpit!$Q$33 -> 49.069667 | P16: =L16-O16 -> -59.197583 | R16: =$AL$9 -> 125000 | S16: =$AL$10 -> 0.8 | T16: =R16*S16 -> 100000 | U16: =U15-$U$7 -> 0.034 | V16: =$AL$12 -> 0.023 | W16: =$AL$13 -> 529.375 | X16: =W16+Cockpit!$K$9 -> 640.375 | Y16: =-Cockpit!$K$12-Cockpit!$H$25*(Szenarien!W16-Szenarien!$AL$13) -> -210.50292 | Z16: =Cockpit!$Q$21-U16*(T16-$T$13)/12-(U16-$U$13)*$T$13/12 -> -283.33333 | AA16: =Cockpit!$Q$22-V16*(T16-$T$13)/12-(V16-$V$13)*$T$13/12 -> -191.66667 | AB16: =X16+Y16+Z16+AA16 -> -45.127917 | AC16: =Cockpit!$Q$29 -> -156 | AD16: =Cockpit!$Q$31-Cockpit!$H$20*Cockpit!$H$21*(1+Cockpit!$D$22)*(R16-$R13)/12 -> -102.84375 | AE16: =(X16+Z16+AC16+AD16)*Cockpit!$Q$33 -> 39.279167 | AF16: =AB16-AE16 -> -84.407083
B17: =B16-$B$7 -> 105000 | C17: =$AL$10 -> 0.8 | D17: =B17*C17 -> 84000 | E17: =$AL$11 -> 0.037 | F17: =$AL$12 -> 0.023 | G17: =$AL$13 -> 529.375 | H17: =G17+Cockpit!$K$9 -> 640.375 | I17: =-Cockpit!$K$12-Cockpit!$H$25*(Szenarien!G17-Szenarien!$AL$13) -> -210.50292 | J17: =Cockpit!$Q$21-E17*(D17-$D13)/12 -> -259 | K17: =Cockpit!$Q$22-F17*(D17-$D13)/12 -> -161 | L17: =H17+I17+J17+K17 -> 9.8720833 | M17: =Cockpit!$Q$29 -> -156 | N17: =Cockpit!$Q$31-Cockpit!$H$20*Cockpit!$H$21*(1+Cockpit!$D$22)*(B17-$B13)/12 -> -86.20875 | O17: =(H17+J17+M17+N17)*Cockpit!$Q$33 -> 55.6665 | P17: =L17-O17 -> -45.794417 | R17: =$AL$9 -> 125000 | S17: =$AL$10 -> 0.8 | T17: =R17*S17 -> 100000 | U17: =U16-$U$7 -> 0.033 | V17: =$AL$12 -> 0.023 | W17: =$AL$13 -> 529.375 | X17: =W17+Cockpit!$K$9 -> 640.375 | Y17: =-Cockpit!$K$12-Cockpit!$H$25*(Szenarien!W17-Szenarien!$AL$13) -> -210.50292 | Z17: =Cockpit!$Q$21-U17*(T17-$T$13)/12-(U17-$U$13)*$T$13/12 -> -275 | AA17: =Cockpit!$Q$22-V17*(T17-$T$13)/12-(V17-$V$13)*$T$13/12 -> -191.66667 | AB17: =X17+Y17+Z17+AA17 -> -36.794583 | AC17: =Cockpit!$Q$29 -> -156 | AD17: =Cockpit!$Q$31-Cockpit!$H$20*Cockpit!$H$21*(1+Cockpit!$D$22)*(R17-$R13)/12 -> -102.84375 | AE17: =(X17+Z17+AC17+AD17)*Cockpit!$Q$33 -> 42.6125 | AF17: =AB17-AE17 -> -79.407083
C20: Sprünge | V20: Sprünge | AM20: Sprünge
B21: Kaufpreis | C21: 0.05 | D21: Darlehen I Summe | E21: Darlehen I Zinssatz | F21: Darlehen I Tilgung | G21: Kaltmiete | H21: Bruttokaltmiete | I21: Bewirtschaftungskosten | J21: Zinsen | K21: Tilgung | L21: CF operativ | M21: Hausgeld und weitere Kosten | N21: AfA | O21: Steuern | P21: Cashflow nach Steuern (Monat) | R21: Kaufpreis | S21: Darlehen I % Kaufpreis | T21: Darlehen I Summe | U21: Darlehen I Zinssatz | V21: 0.005 | W21: Kaltmiete | X21: Bruttokaltmiete | Y21: Bewirtschaftungskosten | Z21: Zinsen | AA21: Tilgung | AB21: CF operativ | AC21: Hausgeld und weitere Kosten | AD21: AfA | AE21: Steuern | AF21: Cashflow nach Steuern (Monat) | AH21: Kaufpreis | AI21: Darlehen I % Kaufpreis | AJ21: Darlehen I Summe | AK21: Darlehen I Zinssatz | AL21: Darlehen I Tilgung | AM21: 20 | AN21: Bruttokaltmiete | AO21: Bewirtschaftungskosten | AP21: Zinsen | AQ21: Tilgung | AR21: CF operativ | AS21: Hausgeld und weitere Kosten | AT21: AfA | AU21: Steuern | AV21: Cashflow nach Steuern (Monat)
C22: % Kaufpreis | V22: Tilgung | AM22: Kaltmiete
B23: =$AL$9 -> 125000 | C23: =C24+$C$21 -> 1 | D23: =C23*B23 -> 125000 | E23: =$AL$11 -> 0.037 | F23: =$AL$12 -> 0.023 | G23: =$AL$13 -> 529.375 | H23: =G23+Cockpit!$K$9 -> 640.375 | I23: =-Cockpit!$K$12-Cockpit!$H$25*(Szenarien!G23-Szenarien!$AL$13) -> -210.50292 | J23: =Cockpit!$Q$21-E23*(D23-$D27)/12 -> -385.41667 | K23: =Cockpit!$Q$22-F23*(D23-$D27)/12 -> -239.58333 | L23: =H23+I23+J23+K23 -> -195.12792 | M23: =Cockpit!$Q$29 -> -156 | N23: =Cockpit!$Q$31-Cockpit!$H$20*Cockpit!$H$21*(1+Cockpit!$D$22)*(B23-$B27)/12 -> -102.84375 | O23: =(H23+J23+M23+N23)*Cockpit!$Q$33 -> -1.5541667 | P23: =L23-O23 -> -193.57375 | R23: =$AL$9 -> 125000 | S23: =$AL$10 -> 0.8 | T23: =R23*S23 -> 100000 | U23: =$AL$11 -> 0.037 | V23: =V24+$V$21 -> 0.043 | W23: =$AL$13 -> 529.375 | X23: =W23+Cockpit!$K$9 -> 640.375 | Y23: =-Cockpit!$K$12-Cockpit!$H$25*(Szenarien!W23-Szenarien!$AL$13) -> -210.50292 | Z23: =Cockpit!$Q$21-U23*(T23-$T$13)/12-(U23-$U$13)*$T$13/12 -> -308.33333 | AA23: =Cockpit!$Q$22-V23*(T23-$T$13)/12-(V23-$V$13)*$T$13/12 -> -358.33333 | AB23: =X23+Y23+Z23+AA23 -> -236.79458 | AC23: =Cockpit!$Q$29 -> -156 | AD23: =Cockpit!$Q$31-Cockpit!$H$20*Cockpit!$H$21*(1+Cockpit!$D$22)*(R23-$R27)/12 -> -102.84375 | AE23: =(X23+Z23+AC23+AD23)*Cockpit!$Q$33 -> 29.279167 | AF23: =AB23-AE23 -> -266.07375 | AH23: =$AL$9 -> 125000 | AI23: =$AL$10 -> 0.8 | AJ23: =AH23*AI23 -> 100000 | AK23: =$AL$11 -> 0.037 | AL23: =$AL$12 -> 0.023 | AM23: =AM24+$AM$21 -> 609.375 | AN23: =AM23+Cockpit!$K$9 -> 720.375 | AO23: =-Cockpit!$K$12-Cockpit!$H$25*(Szenarien!AM23-Szenarien!$AL$13) -> -212.90292 | AP23: =Cockpit!$Q$21-AK23*(AJ23-$T$13)/12-(AK23-$U$13)*$T$13/12 -> -308.33333 | AQ23: =Cockpit!$Q$22-AL23*(AJ23-$T$13)/12-(AL23-$V$13)*$T$13/12 -> -191.66667 | AR23: =AN23+AO23+AP23+AQ23 -> 7.4720833 | AS23: =Cockpit!$Q$29 -> -156 | AT23: =Cockpit!$Q$31-Cockpit!$H$20*Cockpit!$H$21*(1+Cockpit!$D$22)*(AH23-$AH27)/12 -> -102.84375 | AU23: =(AN23+AP23+AS23+AT23)*Cockpit!$Q$33 -> 61.279167 | AV23: =AR23-AU23 -> -53.807083
B24: =$AL$9 -> 125000 | C24: =C25+$C$21 -> 0.95 | D24: =C24*B24 -> 118750 | E24: =$AL$11 -> 0.037 | F24: =$AL$12 -> 0.023 | G24: =$AL$13 -> 529.375 | H24: =G24+Cockpit!$K$9 -> 640.375 | I24: =-Cockpit!$K$12-Cockpit!$H$25*(Szenarien!G24-Szenarien!$AL$13) -> -210.50292 | J24: =Cockpit!$Q$21-E24*(D24-$D27)/12 -> -366.14583 | K24: =Cockpit!$Q$22-F24*(D24-$D27)/12 -> -227.60417 | L24: =H24+I24+J24+K24 -> -163.87792 | M24: =Cockpit!$Q$29 -> -156 | N24: =Cockpit!$Q$31-Cockpit!$H$20*Cockpit!$H$21*(1+Cockpit!$D$22)*(B24-$B27)/12 -> -102.84375 | O24: =(H24+J24+M24+N24)*Cockpit!$Q$33 -> 6.1541667 | P24: =L24-O24 -> -170.03208 | R24: =$AL$9 -> 125000 | S24: =$AL$10 -> 0.8 | T24: =R24*S24 -> 100000 | U24: =$AL$11 -> 0.037 | V24: =V25+$V$21 -> 0.038 | W24: =$AL$13 -> 529.375 | X24: =W24+Cockpit!$K$9 -> 640.375 | Y24: =-Cockpit!$K$12-Cockpit!$H$25*(Szenarien!W24-Szenarien!$AL$13) -> -210.50292 | Z24: =Cockpit!$Q$21-U24*(T24-$T$13)/12-(U24-$U$13)*$T$13/12 -> -308.33333 | AA24: =Cockpit!$Q$22-V24*(T24-$T$13)/12-(V24-$V$13)*$T$13/12 -> -316.66667 | AB24: =X24+Y24+Z24+AA24 -> -195.12792 | AC24: =Cockpit!$Q$29 -> -156 | AD24: =Cockpit!$Q$31-Cockpit!$H$20*Cockpit!$H$21*(1+Cockpit!$D$22)*(R24-$R27)/12 -> -102.84375 | AE24: =(X24+Z24+AC24+AD24)*Cockpit!$Q$33 -> 29.279167 | AF24: =AB24-AE24 -> -224.40708 | AH24: =$AL$9 -> 125000 | AI24: =$AL$10 -> 0.8 | AJ24: =AH24*AI24 -> 100000 | AK24: =$AL$11 -> 0.037 | AL24: =$AL$12 -> 0.023 | AM24: =AM25+$AM$21 -> 589.375 | AN24: =AM24+Cockpit!$K$9 -> 700.375 | AO24: =-Cockpit!$K$12-Cockpit!$H$25*(Szenarien!AM24-Szenarien!$AL$13) -> -212.30292 | AP24: =Cockpit!$Q$21-AK24*(AJ24-$T$13)/12-(AK24-$U$13)*$T$13/12 -> -308.33333 | AQ24: =Cockpit!$Q$22-AL24*(AJ24-$T$13)/12-(AL24-$V$13)*$T$13/12 -> -191.66667 | AR24: =AN24+AO24+AP24+AQ24 -> -11.927917 | AS24: =Cockpit!$Q$29 -> -156 | AT24: =Cockpit!$Q$31-Cockpit!$H$20*Cockpit!$H$21*(1+Cockpit!$D$22)*(AH24-$AH27)/12 -> -102.84375 | AU24: =(AN24+AP24+AS24+AT24)*Cockpit!$Q$33 -> 53.279167 | AV24: =AR24-AU24 -> -65.207083
